<?xml version='1.0'?>

<robot name="my_robot" xmlns:xacro="http://www.ros.org/wiki/xacro">

  <xacro:include filename="$(find my_robot)/urdf/my_robot.gazebo" />

  <link name="robot_footprint"></link>

  <joint name="robot_footprint_joint" type="fixed">
    <origin xyz="0 0 0" rpy="0 0 0" />
    <parent link="robot_footprint"/>
    <child link="chassis" />
  </joint>


  <link name='chassis'>
   <!--<pose>0 0 0.075 0 0 0</pose>-->

    <inertial>
      <mass value="10.0"/>
      <origin xyz="0 0 0.075" rpy=" 0 0 0"/>
      <inertia
          ixx="0.166667" ixy="0" ixz="0"
          iyy="0.166667" iyz="0"
          izz="0.166667"
      />
    </inertial>

    <collision name='chassis_collision'>
      <origin xyz="0 0 0.075" rpy=" 0 0 0"/> 
      <geometry>
        <box size="0.40 0.30 0.09"/>
      </geometry>
    </collision>

    <visual name='chassis_visual'>
      <origin xyz="0 0 0.075" rpy=" 0 0 0"/>
      <geometry>
        <mesh filename="package://my_robot/meshes/MY_CHASIS.dae"/>
      </geometry>
    </visual>

    <collision name='back_caster_wheel_collision'>
      <origin xyz="-0.13 0 0.05" rpy=" 0 0 0"/>
      <geometry>
        <sphere radius="0.05"/>
      </geometry>
    </collision>

    <visual name='back_caster_wheel_visual'>
      <origin xyz="-0.13 0 0.05" rpy=" 0 0 0"/>
      <geometry>
        <sphere radius="0.05"/>
      </geometry>
    </visual>

    <collision name='front_caster_wheel_collision'>
      <origin xyz="0.13 0 0.05" rpy=" 0 0 0"/>
      <geometry>
        <sphere radius="0.05"/>
      </geometry>
    </collision>

    <visual name='front_caster_wheel_visual'>
      <origin xyz="0.13 0 0.05" rpy=" 0 0 0"/>
      <geometry>
        <sphere radius="0.05"/>
      </geometry>
    </visual>

  </link>


  <link name='left_wheel'>
   <!--<pose>0 0.13 0.05 0 0 0</pose>-->

    <inertial>
      <mass value="5.0"/>
      <origin xyz="0.0 0 0" rpy=" 0 0 0"/>
      <inertia
          ixx="0.166667" ixy="0" ixz="0"
          iyy="0.166667" iyz="0"
          izz="0.166667"
      />
    </inertial>

    <collision name='left_wheel_collision'>
      <origin xyz="0 0 0" rpy="0 1.5707 1.5707"/> 
      <geometry>
        <cylinder radius="0.05" length="0.060"/>
      </geometry>
    </collision>

    <visual name='left_wheel_visual'>
      <origin xyz="0 0 0" rpy=" 0 0 0"/>
      <geometry>
        <mesh filename="package://my_robot/meshes/MY_LEFT_WHEEL.dae"/>
      </geometry>
    </visual>
  </link>


  <link name='right_wheel'>
   <!--<pose>0 -0.13 0.05 0 0 0</pose>-->

    <inertial>
      <mass value="5.0"/>
      <origin xyz="0.0 0 0" rpy=" 0 0 0"/>
      <inertia
          ixx="0.166667" ixy="0" ixz="0"
          iyy="0.166667" iyz="0"
          izz="0.166667"
      />
    </inertial>

    <collision name='right_wheel_collision'>
      <origin xyz="0 0 0" rpy="0 1.5707 1.5707"/> 
      <geometry>
        <cylinder radius="0.05" length="0.060"/>
      </geometry>
    </collision>

    <visual name='right_wheel_visual'>
      <origin xyz="0 0 0" rpy=" 0 0 0"/>
      <geometry>
        <mesh filename="package://my_robot/meshes/MY_RIGHT_WHEEL.dae"/>
      </geometry>
    </visual>
  </link>


  <link name='camera'>

    <inertial>
      <mass value="0.1"/>
      <origin xyz="0 0 0" rpy="0 0 0"/>
      <inertia
          ixx="1e-6" ixy="0" ixz="0"
          iyy="1e-6" iyz="0"
          izz="1e-6"
      />
    </inertial>

    <collision name='camera_collision'>
      <origin xyz="0 0 0" rpy="0 0 0"/> 
      <geometry>
        <box size="0.05 0.05 0.05"/>
      </geometry>
    </collision>

    <visual name='camera_visual'>
      <origin xyz="0 0 0" rpy="0 0 0"/>
      <geometry>
        <box size="0.05 0.05 0.05"/>
      </geometry>
    </visual>

  </link>


  <link name='hokuyo'>

    <inertial>
      <mass value="1e-5"/>
      <origin xyz="0.0 0 0" rpy="0 0 0"/>
      <inertia
          ixx="1e-6" ixy="0" ixz="0"
          iyy="1e-6" iyz="0"
          izz="1e-6"
      />
    </inertial>

    <collision name='hokuyo_collision'>
      <origin xyz="0 0 0" rpy="0 0 0"/> 
      <geometry>
        <box size="0.1 0.1 0.1"/>
      </geometry>
    </collision>

    <visual name='hokuyo_visual'>
      <origin xyz="0 0 0" rpy="0 0 0"/>
      <geometry>
        <mesh filename="package://my_robot/meshes/hokuyo.dae"/>
      </geometry>
    </visual>

  </link>

  <link name="camera_link_optical">
  </link>

  <joint type="continuous" name="left_wheel_hinge">
   <!--<pose>0 0.13 0.05 0 0 0</pose>-->
    <origin xyz="0 0.13 0.05" rpy="0 0 0"/>
    <child link="left_wheel"/>
    <parent link="chassis"/>
    <axis xyz="0 1 0" rpy="0 0 0"/>
    <limit effort="10000" velocity="1000"/>
    <dynamics damping="1.0" friction="1.0"/>
  </joint>

  <joint type="continuous" name="right_wheel_hinge">
   <!--<pose>0 -0.13 0.05 0 0 0</pose>-->
    <origin xyz="0 -0.13 0.05" rpy="0 0 0"/>
    <child link="right_wheel"/>
    <parent link="chassis"/>
    <axis xyz="0 1 0" rpy="0 0 0"/>
    <limit effort="10000" velocity="1000"/>
    <dynamics damping="1.0" friction="1.0"/>
  </joint>

  <joint type="fixed" name="camera_joint">
    <origin xyz="0.165 0 0.08" rpy="0 0 0"/>
    <child link="camera"/>
    <parent link="chassis"/>
    <axis xyz="0 1 0" rpy="0 0 0"/>
  </joint>

  <joint type="fixed" name="hokuyo_joint">
    <origin xyz="0.09 0 0.175" rpy="0 0 0"/>
    <child link="hokuyo"/>
    <parent link="chassis"/>
    <axis xyz="0 1 0" rpy="0 0 0"/>
  </joint>

  <joint name="camera_optical_joint" type="fixed">
    <origin xyz="0 0 0" rpy="-1.5707 0 -1.5707"/>
    <parent link="camera"/>
    <child link="camera_link_optical"/>
  </joint>

  <gazebo reference="left_wheel">
    <material>Gazebo/Grey</material>
  </gazebo>

  <gazebo reference="right_wheel">
    <material>Gazebo/Grey</material>
  </gazebo>

  <gazebo reference="chassis">
    <material>Gazebo/Blue</material>
  </gazebo>

  <gazebo reference="camera">
    <material>Gazebo/Green</material>
  </gazebo>

</robot>

